[2023-09-25 18:14:23,197] ERROR log_exception() L1449 Exception on / [POST] - call_trace=C:\Users\Lucas\dev\Pos Eng Soft Puc RJ\mvp-2\user_api\env\Lib\site-packages\flask\app.py L1449
Traceback (most recent call last):
  File "C:\Users\Lucas\dev\Pos Eng Soft Puc RJ\mvp-2\user_api\env\Lib\site-packages\flask\app.py", line 2073, in wsgi_app
    response = self.full_dispatch_request()
               ^^^^^^^^^^^^^^^^^^^^^^^^^^^^
  File "C:\Users\Lucas\dev\Pos Eng Soft Puc RJ\mvp-2\user_api\env\Lib\site-packages\flask\app.py", line 1519, in full_dispatch_request
    rv = self.handle_user_exception(e)
         ^^^^^^^^^^^^^^^^^^^^^^^^^^^^^
  File "C:\Users\Lucas\dev\Pos Eng Soft Puc RJ\mvp-2\user_api\env\Lib\site-packages\flask_cors\extension.py", line 165, in wrapped_function
    return cors_after_request(app.make_response(f(*args, **kwargs)))
                                                ^^^^^^^^^^^^^^^^^^
  File "C:\Users\Lucas\dev\Pos Eng Soft Puc RJ\mvp-2\user_api\env\Lib\site-packages\flask\app.py", line 1517, in full_dispatch_request
    rv = self.dispatch_request()
         ^^^^^^^^^^^^^^^^^^^^^^^
  File "C:\Users\Lucas\dev\Pos Eng Soft Puc RJ\mvp-2\user_api\env\Lib\site-packages\flask\app.py", line 1503, in dispatch_request
    return self.ensure_sync(self.view_functions[rule.endpoint])(**req.view_args)
           ^^^^^^^^^^^^^^^^^^^^^^^^^^^^^^^^^^^^^^^^^^^^^^^^^^^^^^^^^^^^^^^^^^^^^
  File "C:\Users\Lucas\dev\Pos Eng Soft Puc RJ\mvp-2\user_api\env\Lib\site-packages\flask_openapi3\scaffold.py", line 191, in wrapper
    resp = _do_wrapper(
           ^^^^^^^^^^^^
  File "C:\Users\Lucas\dev\Pos Eng Soft Puc RJ\mvp-2\user_api\env\Lib\site-packages\flask_openapi3\do_wrapper.py", line 135, in _do_wrapper
    response = func(**request_kwargs)
               ^^^^^^^^^^^^^^^^^^^^^^
  File "C:\Users\Lucas\dev\Pos Eng Soft Puc RJ\mvp-2\list_api\app.py", line 34, in add_list
    logger.debug(f"Adicionando lista de nome: '{gamelist.name}'")
                                                ^^^^^^^^
UnboundLocalError: cannot access local variable 'gamelist' where it is not associated with a value
[2023-09-25 18:14:23,207] INFO _log() L224  127.0.0.1 - - [25/Sep/2023 18:14:23] "[35m[1mPOST / HTTP/1.1[0m" 500 - - call_trace=C:\Users\Lucas\dev\Pos Eng Soft Puc RJ\mvp-2\user_api\env\Lib\site-packages\werkzeug\_internal.py L224 
[2023-09-25 18:15:01,917] INFO _log() L224   * Running on all addresses (0.0.0.0)
   WARNING: This is a development server. Do not use it in a production deployment.
 * Running on http://127.0.0.1:5001
 * Running on http://192.168.15.8:5001 (Press CTRL+C to quit) - call_trace=C:\Users\Lucas\dev\Pos Eng Soft Puc RJ\mvp-2\user_api\env\Lib\site-packages\werkzeug\_internal.py L224 
[2023-09-25 18:15:13,337] INFO _log() L224  127.0.0.1 - - [25/Sep/2023 18:15:13] "[31m[1mPOST / HTTP/1.1[0m" 401 - - call_trace=C:\Users\Lucas\dev\Pos Eng Soft Puc RJ\mvp-2\user_api\env\Lib\site-packages\werkzeug\_internal.py L224 
[2023-09-25 18:15:55,011] INFO _log() L224   * Running on all addresses (0.0.0.0)
   WARNING: This is a development server. Do not use it in a production deployment.
 * Running on http://127.0.0.1:5001
 * Running on http://192.168.15.8:5001 (Press CTRL+C to quit) - call_trace=C:\Users\Lucas\dev\Pos Eng Soft Puc RJ\mvp-2\user_api\env\Lib\site-packages\werkzeug\_internal.py L224 
[2023-09-25 18:15:57,807] ERROR log_exception() L1449 Exception on / [POST] - call_trace=C:\Users\Lucas\dev\Pos Eng Soft Puc RJ\mvp-2\user_api\env\Lib\site-packages\flask\app.py L1449
Traceback (most recent call last):
  File "C:\Users\Lucas\dev\Pos Eng Soft Puc RJ\mvp-2\list_api\app.py", line 40, in add_list
    user = readToken(token)['user']
           ~~~~~~~~~~~~~~~~^^^^^^^^
KeyError: 'user'

During handling of the above exception, another exception occurred:

Traceback (most recent call last):
  File "C:\Users\Lucas\dev\Pos Eng Soft Puc RJ\mvp-2\user_api\env\Lib\site-packages\flask\app.py", line 2073, in wsgi_app
    response = self.full_dispatch_request()
               ^^^^^^^^^^^^^^^^^^^^^^^^^^^^
  File "C:\Users\Lucas\dev\Pos Eng Soft Puc RJ\mvp-2\user_api\env\Lib\site-packages\flask\app.py", line 1519, in full_dispatch_request
    rv = self.handle_user_exception(e)
         ^^^^^^^^^^^^^^^^^^^^^^^^^^^^^
  File "C:\Users\Lucas\dev\Pos Eng Soft Puc RJ\mvp-2\user_api\env\Lib\site-packages\flask_cors\extension.py", line 165, in wrapped_function
    return cors_after_request(app.make_response(f(*args, **kwargs)))
                                                ^^^^^^^^^^^^^^^^^^
  File "C:\Users\Lucas\dev\Pos Eng Soft Puc RJ\mvp-2\user_api\env\Lib\site-packages\flask\app.py", line 1517, in full_dispatch_request
    rv = self.dispatch_request()
         ^^^^^^^^^^^^^^^^^^^^^^^
  File "C:\Users\Lucas\dev\Pos Eng Soft Puc RJ\mvp-2\user_api\env\Lib\site-packages\flask\app.py", line 1503, in dispatch_request
    return self.ensure_sync(self.view_functions[rule.endpoint])(**req.view_args)
           ^^^^^^^^^^^^^^^^^^^^^^^^^^^^^^^^^^^^^^^^^^^^^^^^^^^^^^^^^^^^^^^^^^^^^
  File "C:\Users\Lucas\dev\Pos Eng Soft Puc RJ\mvp-2\user_api\env\Lib\site-packages\flask_openapi3\scaffold.py", line 191, in wrapper
    resp = _do_wrapper(
           ^^^^^^^^^^^^
  File "C:\Users\Lucas\dev\Pos Eng Soft Puc RJ\mvp-2\user_api\env\Lib\site-packages\flask_openapi3\do_wrapper.py", line 135, in _do_wrapper
    response = func(**request_kwargs)
               ^^^^^^^^^^^^^^^^^^^^^^
  File "C:\Users\Lucas\dev\Pos Eng Soft Puc RJ\mvp-2\list_api\app.py", line 73, in add_list
    f"Erro ao adicionar lista '{gamelist.name}', {e}")
                                ^^^^^^^^
UnboundLocalError: cannot access local variable 'gamelist' where it is not associated with a value
[2023-09-25 18:15:57,813] INFO _log() L224  127.0.0.1 - - [25/Sep/2023 18:15:57] "[35m[1mPOST / HTTP/1.1[0m" 500 - - call_trace=C:\Users\Lucas\dev\Pos Eng Soft Puc RJ\mvp-2\user_api\env\Lib\site-packages\werkzeug\_internal.py L224 
[2023-09-25 18:17:25,704] INFO _log() L224   * Running on all addresses (0.0.0.0)
   WARNING: This is a development server. Do not use it in a production deployment.
 * Running on http://127.0.0.1:5001
 * Running on http://192.168.15.8:5001 (Press CTRL+C to quit) - call_trace=C:\Users\Lucas\dev\Pos Eng Soft Puc RJ\mvp-2\user_api\env\Lib\site-packages\werkzeug\_internal.py L224 
[2023-09-25 18:17:27,629] INFO _log() L224  127.0.0.1 - - [25/Sep/2023 18:17:27] "[31m[1mPOST / HTTP/1.1[0m" 401 - - call_trace=C:\Users\Lucas\dev\Pos Eng Soft Puc RJ\mvp-2\user_api\env\Lib\site-packages\werkzeug\_internal.py L224 
[2023-09-25 18:17:40,777] INFO _log() L224  127.0.0.1 - - [25/Sep/2023 18:17:40] "[31m[1mPOST / HTTP/1.1[0m" 401 - - call_trace=C:\Users\Lucas\dev\Pos Eng Soft Puc RJ\mvp-2\user_api\env\Lib\site-packages\werkzeug\_internal.py L224 
[2023-09-25 18:17:47,901] INFO _log() L224   * Running on all addresses (0.0.0.0)
   WARNING: This is a development server. Do not use it in a production deployment.
 * Running on http://127.0.0.1:5001
 * Running on http://192.168.15.8:5001 (Press CTRL+C to quit) - call_trace=C:\Users\Lucas\dev\Pos Eng Soft Puc RJ\mvp-2\user_api\env\Lib\site-packages\werkzeug\_internal.py L224 
[2023-09-25 18:17:49,486] INFO _log() L224  127.0.0.1 - - [25/Sep/2023 18:17:49] "[31m[1mPOST / HTTP/1.1[0m" 401 - - call_trace=C:\Users\Lucas\dev\Pos Eng Soft Puc RJ\mvp-2\user_api\env\Lib\site-packages\werkzeug\_internal.py L224 
[2023-09-25 18:18:22,627] INFO _log() L224   * Running on all addresses (0.0.0.0)
   WARNING: This is a development server. Do not use it in a production deployment.
 * Running on http://127.0.0.1:5001
 * Running on http://192.168.15.8:5001 (Press CTRL+C to quit) - call_trace=C:\Users\Lucas\dev\Pos Eng Soft Puc RJ\mvp-2\user_api\env\Lib\site-packages\werkzeug\_internal.py L224 
[2023-09-25 18:18:24,164] INFO _log() L224  127.0.0.1 - - [25/Sep/2023 18:18:24] "[31m[1mPOST / HTTP/1.1[0m" 403 - - call_trace=C:\Users\Lucas\dev\Pos Eng Soft Puc RJ\mvp-2\user_api\env\Lib\site-packages\werkzeug\_internal.py L224 
[2023-09-25 18:20:57,951] INFO _log() L224   * Running on all addresses (0.0.0.0)
   WARNING: This is a development server. Do not use it in a production deployment.
 * Running on http://127.0.0.1:5001
 * Running on http://192.168.15.8:5001 (Press CTRL+C to quit) - call_trace=C:\Users\Lucas\dev\Pos Eng Soft Puc RJ\mvp-2\user_api\env\Lib\site-packages\werkzeug\_internal.py L224 
[2023-09-25 18:23:43,367] INFO _log() L224  127.0.0.1 - - [25/Sep/2023 18:23:43] "[36mGET /openapi/static/images/swagger.svg HTTP/1.1[0m" 304 - - call_trace=C:\Users\Lucas\dev\Pos Eng Soft Puc RJ\mvp-2\user_api\env\Lib\site-packages\werkzeug\_internal.py L224 
[2023-09-25 18:23:46,179] INFO _log() L224  127.0.0.1 - - [25/Sep/2023 18:23:46] "GET / HTTP/1.1" 200 - - call_trace=C:\Users\Lucas\dev\Pos Eng Soft Puc RJ\mvp-2\user_api\env\Lib\site-packages\werkzeug\_internal.py L224 
[2023-09-25 18:23:51,602] INFO _log() L224  127.0.0.1 - - [25/Sep/2023 18:23:51] "[36mGET /openapi/static/images/swagger.svg HTTP/1.1[0m" 304 - - call_trace=C:\Users\Lucas\dev\Pos Eng Soft Puc RJ\mvp-2\user_api\env\Lib\site-packages\werkzeug\_internal.py L224 
[2023-09-25 18:23:52,332] INFO _log() L224  127.0.0.1 - - [25/Sep/2023 18:23:52] "[36mGET /openapi/static/images/swagger.svg HTTP/1.1[0m" 304 - - call_trace=C:\Users\Lucas\dev\Pos Eng Soft Puc RJ\mvp-2\user_api\env\Lib\site-packages\werkzeug\_internal.py L224 
[2023-09-25 18:23:54,741] INFO _log() L224  127.0.0.1 - - [25/Sep/2023 18:23:54] "GET /:id?id=3 HTTP/1.1" 200 - - call_trace=C:\Users\Lucas\dev\Pos Eng Soft Puc RJ\mvp-2\user_api\env\Lib\site-packages\werkzeug\_internal.py L224 
