[2023-09-25 17:37:29,119] INFO _log() L224  127.0.0.1 - - [25/Sep/2023 17:37:29] "[36mGET /openapi/static/js/swagger-ui-standalone-preset.js HTTP/1.1[0m" 304 - - call_trace=C:\Users\Lucas\dev\Pos Eng Soft Puc RJ\mvp-2\user_api\env\Lib\site-packages\werkzeug\_internal.py L224 
[2023-09-25 17:37:29,267] INFO _log() L224  127.0.0.1 - - [25/Sep/2023 17:37:29] "GET /openapi/openapi.json HTTP/1.1" 200 - - call_trace=C:\Users\Lucas\dev\Pos Eng Soft Puc RJ\mvp-2\user_api\env\Lib\site-packages\werkzeug\_internal.py L224 
[2023-09-25 17:37:29,572] INFO _log() L224  127.0.0.1 - - [25/Sep/2023 17:37:29] "[36mGET /openapi/static/images/swagger.svg HTTP/1.1[0m" 304 - - call_trace=C:\Users\Lucas\dev\Pos Eng Soft Puc RJ\mvp-2\user_api\env\Lib\site-packages\werkzeug\_internal.py L224 
[2023-09-25 17:37:43,586] INFO _log() L224  127.0.0.1 - - [25/Sep/2023 17:37:43] "[31m[1mGET /me HTTP/1.1[0m" 401 - - call_trace=C:\Users\Lucas\dev\Pos Eng Soft Puc RJ\mvp-2\user_api\env\Lib\site-packages\werkzeug\_internal.py L224 
[2023-09-25 17:38:02,362] INFO _log() L224  127.0.0.1 - - [25/Sep/2023 17:38:02] "GET /me HTTP/1.1" 200 - - call_trace=C:\Users\Lucas\dev\Pos Eng Soft Puc RJ\mvp-2\user_api\env\Lib\site-packages\werkzeug\_internal.py L224 
[2023-09-25 17:38:17,304] INFO _log() L224  127.0.0.1 - - [25/Sep/2023 17:38:17] "GET /me HTTP/1.1" 200 - - call_trace=C:\Users\Lucas\dev\Pos Eng Soft Puc RJ\mvp-2\user_api\env\Lib\site-packages\werkzeug\_internal.py L224 
[2023-09-25 17:41:11,823] INFO _log() L224   * Running on all addresses (0.0.0.0)
   WARNING: This is a development server. Do not use it in a production deployment.
 * Running on http://127.0.0.1:5001
 * Running on http://192.168.15.8:5001 (Press CTRL+C to quit) - call_trace=C:\Users\Lucas\dev\Pos Eng Soft Puc RJ\mvp-2\user_api\env\Lib\site-packages\werkzeug\_internal.py L224 
[2023-09-25 17:41:14,168] ERROR log_exception() L1449 Exception on /me [GET] - call_trace=C:\Users\Lucas\dev\Pos Eng Soft Puc RJ\mvp-2\user_api\env\Lib\site-packages\flask\app.py L1449
Traceback (most recent call last):
  File "C:\Users\Lucas\dev\Pos Eng Soft Puc RJ\mvp-2\user_api\env\Lib\site-packages\flask\app.py", line 2073, in wsgi_app
    response = self.full_dispatch_request()
               ^^^^^^^^^^^^^^^^^^^^^^^^^^^^
  File "C:\Users\Lucas\dev\Pos Eng Soft Puc RJ\mvp-2\user_api\env\Lib\site-packages\flask\app.py", line 1519, in full_dispatch_request
    rv = self.handle_user_exception(e)
         ^^^^^^^^^^^^^^^^^^^^^^^^^^^^^
  File "C:\Users\Lucas\dev\Pos Eng Soft Puc RJ\mvp-2\user_api\env\Lib\site-packages\flask_cors\extension.py", line 165, in wrapped_function
    return cors_after_request(app.make_response(f(*args, **kwargs)))
                                                ^^^^^^^^^^^^^^^^^^
  File "C:\Users\Lucas\dev\Pos Eng Soft Puc RJ\mvp-2\user_api\env\Lib\site-packages\flask\app.py", line 1517, in full_dispatch_request
    rv = self.dispatch_request()
         ^^^^^^^^^^^^^^^^^^^^^^^
  File "C:\Users\Lucas\dev\Pos Eng Soft Puc RJ\mvp-2\user_api\env\Lib\site-packages\flask\app.py", line 1503, in dispatch_request
    return self.ensure_sync(self.view_functions[rule.endpoint])(**req.view_args)
           ^^^^^^^^^^^^^^^^^^^^^^^^^^^^^^^^^^^^^^^^^^^^^^^^^^^^^^^^^^^^^^^^^^^^^
  File "C:\Users\Lucas\dev\Pos Eng Soft Puc RJ\mvp-2\user_api\env\Lib\site-packages\flask_openapi3\scaffold.py", line 109, in wrapper
    resp = _do_wrapper(
           ^^^^^^^^^^^^
  File "C:\Users\Lucas\dev\Pos Eng Soft Puc RJ\mvp-2\user_api\env\Lib\site-packages\flask_openapi3\do_wrapper.py", line 135, in _do_wrapper
    response = func(**request_kwargs)
               ^^^^^^^^^^^^^^^^^^^^^^
  File "C:\Users\Lucas\dev\Pos Eng Soft Puc RJ\mvp-2\list_api\app.py", line 90, in get_my_lists
    user = readToken(token)
           ^^^^^^^^^^^^^^^^
  File "C:\Users\Lucas\dev\Pos Eng Soft Puc RJ\mvp-2\list_api\utils\token.py", line 7, in readToken
    return jwt.decode(token, secret, algorithm="HS256")
           ^^^^^^^^^^^^^^^^^^^^^^^^^^^^^^^^^^^^^^^^^^^^
  File "C:\Users\Lucas\dev\Pos Eng Soft Puc RJ\mvp-2\user_api\env\Lib\site-packages\jwt\api_jwt.py", line 210, in decode
    decoded = self.decode_complete(
              ^^^^^^^^^^^^^^^^^^^^^
  File "C:\Users\Lucas\dev\Pos Eng Soft Puc RJ\mvp-2\user_api\env\Lib\site-packages\jwt\api_jwt.py", line 147, in decode_complete
    raise DecodeError(
jwt.exceptions.DecodeError: It is required that you pass in a value for the "algorithms" argument when calling decode().
[2023-09-25 17:41:14,187] INFO _log() L224  127.0.0.1 - - [25/Sep/2023 17:41:14] "[35m[1mGET /me HTTP/1.1[0m" 500 - - call_trace=C:\Users\Lucas\dev\Pos Eng Soft Puc RJ\mvp-2\user_api\env\Lib\site-packages\werkzeug\_internal.py L224 
[2023-09-25 17:42:09,016] INFO _log() L224   * Running on all addresses (0.0.0.0)
   WARNING: This is a development server. Do not use it in a production deployment.
 * Running on http://127.0.0.1:5001
 * Running on http://192.168.15.8:5001 (Press CTRL+C to quit) - call_trace=C:\Users\Lucas\dev\Pos Eng Soft Puc RJ\mvp-2\user_api\env\Lib\site-packages\werkzeug\_internal.py L224 
